Workbook

Sheet DSO
B1: Uddokta wise DSO Sales SUMMARY | C1: =SUBTOTAL(103,C3:C1934) -> 50 | D1: =SUBTOTAL(109,D3:D1934) -> 365024.95 | E1: =SUBTOTAL(109,E3:E1934) -> 121322 | F1: =SUBTOTAL(109,F3:F1934) -> 770735 | G1: =SUBTOTAL(109,G3:G1934) -> 109000 | H1: =SUBTOTAL(109,H3:H1934) -> 994000 | I1: =SUBTOTAL(109,I3:I1934) -> 1013000
A2: DSO | B2: AGENT SHOP NAME | C2: UDDOKTA | D2: BALANCE | E2: Cash In | F2: (CI+CO) | G2: B2BS_AMT | H2: B2BR_AMT | I2: B2B GAP
A3: 01334764501 | B3: M/S Halim Pharmacy | C3: 01773127707 | D3: =SUMIF(RAW_File!D:D,C:C,RAW_File!F:F) -> 878.12966 | E3: =SUMIF(RAW_File!D:D,C:C,RAW_File!G:G) -> 910 | F3: =SUMIF(RAW_File!D:D,C:C,RAW_File!I:I) -> 2910 | G3: =SUMIF(RAW_File!D:D,C:C,RAW_File!K:K) -> 0 | H3: =SUMIF(RAW_File!D:D,C:C,RAW_File!M:M) -> 5000 | I3: =ABS(G3-H3) -> 5000
A4: 01334764501 | B4: Sojib Pharmacy | C4: 01311964806 | D4: =SUMIF(RAW_File!D:D,C:C,RAW_File!F:F) -> 7817.2392 | E4: =SUMIF(RAW_File!D:D,C:C,RAW_File!G:G) -> 6400 | F4: =SUMIF(RAW_File!D:D,C:C,RAW_File!I:I) -> 15930 | G4: =SUMIF(RAW_File!D:D,C:C,RAW_File!K:K) -> 0 | H4: =SUMIF(RAW_File!D:D,C:C,RAW_File!M:M) -> 20000 | I4: =ABS(G4-H4) -> 20000
A5: 01334764501 | B5: MIRAZ STORE | C5: 01346277833 | D5: =SUMIF(RAW_File!D:D,C:C,RAW_File!F:F) -> 18780.997 | E5: =SUMIF(RAW_File!D:D,C:C,RAW_File!G:G) -> 2015 | F5: =SUMIF(RAW_File!D:D,C:C,RAW_File!I:I) -> 20795 | G5: =SUMIF(RAW_File!D:D,C:C,RAW_File!K:K) -> 0 | H5: =SUMIF(RAW_File!D:D,C:C,RAW_File!M:M) -> 7000 | I5: =ABS(G5-H5) -> 7000
A6: 01334764501 | B6: MUN PHARMACY | C6: 01788654188 | D6: =SUMIF(RAW_File!D:D,C:C,RAW_File!F:F) -> 6493.2379 | E6: =SUMIF(RAW_File!D:D,C:C,RAW_File!G:G) -> 0 | F6: =SUMIF(RAW_File!D:D,C:C,RAW_File!I:I) -> 3670 | G6: =SUMIF(RAW_File!D:D,C:C,RAW_File!K:K) -> 0 | H6: =SUMIF(RAW_File!D:D,C:C,RAW_File!M:M) -> 7000 | I6: =ABS(G6-H6) -> 7000
A7: 01334764501 | B7: SHAKILA STORE | C7: 01748586837 | D7: =SUMIF(RAW_File!D:D,C:C,RAW_File!F:F) -> 13.21375 | E7: =SUMIF(RAW_File!D:D,C:C,RAW_File!G:G) -> 0 | F7: =SUMIF(RAW_File!D:D,C:C,RAW_File!I:I) -> 0 | G7: =SUMIF(RAW_File!D:D,C:C,RAW_File!K:K) -> 0 | H7: =SUMIF(RAW_File!D:D,C:C,RAW_File!M:M) -> 0 | I7: =ABS(G7-H7) -> 0
A8: 01334764501 | B8: Kasem Telecom | C8: 01774502529 | D8: =SUMIF(RAW_File!D:D,C:C,RAW_File!F:F) -> 350.57996 | E8: =SUMIF(RAW_File!D:D,C:C,RAW_File!G:G) -> 53830 | F8: =SUMIF(RAW_File!D:D,C:C,RAW_File!I:I) -> 78410 | G8: =SUMIF(RAW_File!D:D,C:C,RAW_File!K:K) -> 12000 | H8: =SUMIF(RAW_File!D:D,C:C,RAW_File!M:M) -> 0 | I8: =ABS(G8-H8) -> 12000
A9: 01334764501 | B9: MAHABUB TRADERS | C9: 01779963542 | D9: =SUMIF(RAW_File!D:D,C:C,RAW_File!F:F) -> 8106.3919 | E9: =SUMIF(RAW_File!D:D,C:C,RAW_File!G:G) -> 1010 | F9: =SUMIF(RAW_File!D:D,C:C,RAW_File!I:I) -> 1010 | G9: =SUMIF(RAW_File!D:D,C:C,RAW_File!K:K) -> 0 | H9: =SUMIF(RAW_File!D:D,C:C,RAW_File!M:M) -> 6000 | I9: =ABS(G9-H9) -> 6000
A10: 01334764501 | B10: KHAYRUL STORE | C10: 01864775506 | D10: =SUMIF(RAW_File!D:D,C:C,RAW_File!F:F) -> 11219.952 | E10: =SUMIF(RAW_File!D:D,C:C,RAW_File!G:G) -> 4970 | F10: =SUMIF(RAW_File!D:D,C:C,RAW_File!I:I) -> 15170 | G10: =SUMIF(RAW_File!D:D,C:C,RAW_File!K:K) -> 0 | H10: =SUMIF(RAW_File!D:D,C:C,RAW_File!M:M) -> 20000 | I10: =ABS(G10-H10) -> 20000
A11: 01334764501 | B11: SINHA TRADERS | C11: 01774849696 | D11: =SUMIF(RAW_File!D:D,C:C,RAW_File!F:F) -> 0.60835219 | E11: =SUMIF(RAW_File!D:D,C:C,RAW_File!G:G) -> 6190 | F11: =SUMIF(RAW_File!D:D,C:C,RAW_File!I:I) -> 12280 | G11: =SUMIF(RAW_File!D:D,C:C,RAW_File!K:K) -> 0 | H11: =SUMIF(RAW_File!D:D,C:C,RAW_File!M:M) -> 6000 | I11: =ABS(G11-H11) -> 6000
A12: 01334764501 | B12: Rakib Store | C12: 01315277783 | D12: =SUMIF(RAW_File!D:D,C:C,RAW_File!F:F) -> 294.76536 | E12: =SUMIF(RAW_File!D:D,C:C,RAW_File!G:G) -> 15365 | F12: =SUMIF(RAW_File!D:D,C:C,RAW_File!I:I) -> 15931 | G12: =SUMIF(RAW_File!D:D,C:C,RAW_File!K:K) -> 17000 | H12: =SUMIF(RAW_File!D:D,C:C,RAW_File!M:M) -> 2000 | I12: =ABS(G12-H12) -> 15000
A13: 01334764501 | B13: INSIRA VARIETIES STORE | C13: 01331596807 | D13: =SUMIF(RAW_File!D:D,C:C,RAW_File!F:F) -> 12780.577 | E13: =SUMIF(RAW_File!D:D,C:C,RAW_File!G:G) -> 1100 | F13: =SUMIF(RAW_File!D:D,C:C,RAW_File!I:I) -> 11814 | G13: =SUMIF(RAW_File!D:D,C:C,RAW_File!K:K) -> 0 | H13: =SUMIF(RAW_File!D:D,C:C,RAW_File!M:M) -> 20000 | I13: =ABS(G13-H13) -> 20000
A14: 01334764501 | B14: MAA BABA DOYA | C14: 01630075751 | D14: =SUMIF(RAW_File!D:D,C:C,RAW_File!F:F) -> 11293.175 | E14: =SUMIF(RAW_File!D:D,C:C,RAW_File!G:G) -> 14850 | F14: =SUMIF(RAW_File!D:D,C:C,RAW_File!I:I) -> 43580 | G14: =SUMIF(RAW_File!D:D,C:C,RAW_File!K:K) -> 0 | H14: =SUMIF(RAW_File!D:D,C:C,RAW_File!M:M) -> 16000 | I14: =ABS(G14-H14) -> 16000
... A1474: 01334764532 | B1474: Onika Fashon Su Store | C1474: 01750600324 | D1474: =SUMIF(RAW_File!D:D,C:C,RAW_File!F:F) -> 3888.376 | E1474: =SUMIF(RAW_File!D:D,C:C,RAW_File!G:G) -> 5000 | F1474: =SUMIF(RAW_File!D:D,C:C,RAW_File!I:I) -> 5000 | G1474: =SUMIF(RAW_File!D:D,C:C,RAW_File!K:K) -> 5000 | H1474: =SUMIF(RAW_File!D:D,C:C,RAW_File!M:M) -> 0 | I1474: =ABS(G1474-H1474) -> 5000
A1475: 01334764532 | B1475: PONCHANAN ROY DIGITAL STUDIO | C1475: 01346263106
A1476: 01334764532 | B1476: M/S RANA VARIETIES STORE | C1476: 01346370390
A1477: 01334764533 | B1477: SAKIL TELECOM | C1477: 01729898773 | D1477: =SUMIF(RAW_File!D:D,C:C,RAW_File!F:F) -> 186.48304 | E1477: =SUMIF(RAW_File!D:D,C:C,RAW_File!G:G) -> 7310 | F1477: =SUMIF(RAW_File!D:D,C:C,RAW_File!I:I) -> 7390 | G1477: =SUMIF(RAW_File!D:D,C:C,RAW_File!K:K) -> 6000 | H1477: =SUMIF(RAW_File!D:D,C:C,RAW_File!M:M) -> 0 | I1477: =ABS(G1477-H1477) -> 6000
A1478: 01334764533 | B1478: L . T.S. TELECOM | C1478: 01341329037 | D1478: =SUMIF(RAW_File!D:D,C:C,RAW_File!F:F) -> 12314.261 | E1478: =SUMIF(RAW_File!D:D,C:C,RAW_File!G:G) -> 0 | F1478: =SUMIF(RAW_File!D:D,C:C,RAW_File!I:I) -> 7920 | G1478: =SUMIF(RAW_File!D:D,C:C,RAW_File!K:K) -> 0 | H1478: =SUMIF(RAW_File!D:D,C:C,RAW_File!M:M) -> 5000 | I1478: =ABS(G1478-H1478) -> 5000
A1479: 01334764533 | B1479: MAYER DOYA TELECOM | C1479: 01710538076 | D1479: =SUMIF(RAW_File!D:D,C:C,RAW_File!F:F) -> 17.851791 | E1479: =SUMIF(RAW_File!D:D,C:C,RAW_File!G:G) -> 5110 | F1479: =SUMIF(RAW_File!D:D,C:C,RAW_File!I:I) -> 5200 | G1479: =SUMIF(RAW_File!D:D,C:C,RAW_File!K:K) -> 5000 | H1479: =SUMIF(RAW_File!D:D,C:C,RAW_File!M:M) -> 0 | I1479: =ABS(G1479-H1479) -> 5000
A1480: 01334764533 | B1480: MA TELECOM | C1480: 01755434888 | D1480: =SUMIF(RAW_File!D:D,C:C,RAW_File!F:F) -> 13675.432 | E1480: =SUMIF(RAW_File!D:D,C:C,RAW_File!G:G) -> 5605 | F1480: =SUMIF(RAW_File!D:D,C:C,RAW_File!I:I) -> 20225 | G1480: =SUMIF(RAW_File!D:D,C:C,RAW_File!K:K) -> 0 | H1480: =SUMIF(RAW_File!D:D,C:C,RAW_File!M:M) -> 6000 | I1480: =ABS(G1480-H1480) -> 6000
A1481: 01334764533 | B1481: M/S RIPON TELECOM | C1481: 01796542550 | D1481: =SUMIF(RAW_File!D:D,C:C,RAW_File!F:F) -> 30.613804 | E1481: =SUMIF(RAW_File!D:D,C:C,RAW_File!G:G) -> 203 | F1481: =SUMIF(RAW_File!D:D,C:C,RAW_File!I:I) -> 403 | G1481: =SUMIF(RAW_File!D:D,C:C,RAW_File!K:K) -> 0 | H1481: =SUMIF(RAW_File!D:D,C:C,RAW_File!M:M) -> 0 | I1481: =ABS(G1481-H1481) -> 0
A1482: 01334764533 | B1482: Motaleb Store | C1482: 01750446679 | D1482: =SUMIF(RAW_File!D:D,C:C,RAW_File!F:F) -> 12928.62 | E1482: =SUMIF(RAW_File!D:D,C:C,RAW_File!G:G) -> 0 | F1482: =SUMIF(RAW_File!D:D,C:C,RAW_File!I:I) -> 3200 | G1482: =SUMIF(RAW_File!D:D,C:C,RAW_File!K:K) -> 5000 | H1482: =SUMIF(RAW_File!D:D,C:C,RAW_File!M:M) -> 0 | I1482: =ABS(G1482-H1482) -> 5000
A1483: 01334764533 | B1483: Esmail Telecom | C1483: 01980210005 | D1483: =SUMIF(RAW_File!D:D,C:C,RAW_File!F:F) -> 5501.5818 | E1483: =SUMIF(RAW_File!D:D,C:C,RAW_File!G:G) -> 15568 | F1483: =SUMIF(RAW_File!D:D,C:C,RAW_File!I:I) -> 66062.27 | G1483: =SUMIF(RAW_File!D:D,C:C,RAW_File!K:K) -> 5000 | H1483: =SUMIF(RAW_File!D:D,C:C,RAW_File!M:M) -> 77000 | I1483: =ABS(G1483-H1483) -> 72000
A1484: 01334764533 | B1484: ARAFAT TELECOM | C1484: 01760108845 | D1484: =SUMIF(RAW_File!D:D,C:C,RAW_File!F:F) -> 6401.904 | E1484: =SUMIF(RAW_File!D:D,C:C,RAW_File!G:G) -> 0 | F1484: =SUMIF(RAW_File!D:D,C:C,RAW_File!I:I) -> 500 | G1484: =SUMIF(RAW_File!D:D,C:C,RAW_File!K:K) -> 5000 | H1484: =SUMIF(RAW_File!D:D,C:C,RAW_File!M:M) -> 0 | I1484: =ABS(G1484-H1484) -> 5000
A1485: 01334764533 | B1485: Mobile & Telecom | C1485: 01785270807 | D1485: =SUMIF(RAW_File!D:D,C:C,RAW_File!F:F) -> 46.336632 | E1485: =SUMIF(RAW_File!D:D,C:C,RAW_File!G:G) -> 0 | F1485: =SUMIF(RAW_File!D:D,C:C,RAW_File!I:I) -> 5000 | G1485: =SUMIF(RAW_File!D:D,C:C,RAW_File!K:K) -> 0 | H1485: =SUMIF(RAW_File!D:D,C:C,RAW_File!M:M) -> 5000 | I1485: =ABS(G1485-H1485) -> 5000
A1486: 01334764533 | B1486: Electronice &Telecom | C1486: 01797722456 | D1486: =SUMIF(RAW_File!D:D,C:C,RAW_File!F:F) -> 10367.662 | E1486: =SUMIF(RAW_File!D:D,C:C,RAW_File!G:G) -> 245 | F1486: =SUMIF(RAW_File!D:D,C:C,RAW_File!I:I) -> 27455 | G1486: =SUMIF(RAW_File!D:D,C:C,RAW_File!K:K) -> 0 | H1486: =SUMIF(RAW_File!D:D,C:C,RAW_File!M:M) -> 50000 | I1486: =ABS(G1486-H1486) -> 50000
A1487: 01334764533 | B1487: JAHID STORE | C1487: 01332007011 | D1487: =SUMIF(RAW_File!D:D,C:C,RAW_File!F:F) -> 1131.7103 | E1487: =SUMIF(RAW_File!D:D,C:C,RAW_File!G:G) -> 6330 | F1487: =SUMIF(RAW_File!D:D,C:C,RAW_File!I:I) -> 6330 | G1487: =SUMIF(RAW_File!D:D,C:C,RAW_File!K:K) -> 0 | H1487: =SUMIF(RAW_File!D:D,C:C,RAW_File!M:M) -> 5000 | I1487: =ABS(G1487-H1487) -> 5000
A1488: 01334764533 | B1488: Gobindro Telecom | C1488: 01797915229 | D1488: =SUMIF(RAW_File!D:D,C:C,RAW_File!F:F) -> 5740.2168 | E1488: =SUMIF(RAW_File!D:D,C:C,RAW_File!G:G) -> 3650 | F1488: =SUMIF(RAW_File!D:D,C:C,RAW_File!I:I) -> 15290 | G1488: =SUMIF(RAW_File!D:D,C:C,RAW_File!K:K) -> 5000 | H1488: =SUMIF(RAW_File!D:D,C:C,RAW_File!M:M) -> 25000 | I1488: =ABS(G1488-H1488) -> 20000
... A1772: 01334764538 | B1772: SABIT GARMENTS | C1772: 01798789829 | D1772: =SUMIF(RAW_File!D:D,C:C,RAW_File!F:F) -> 7.5083 | E1772: =SUMIF(RAW_File!D:D,C:C,RAW_File!G:G) -> 0 | F1772: =SUMIF(RAW_File!D:D,C:C,RAW_File!I:I) -> 0 | G1772: =SUMIF(RAW_File!D:D,C:C,RAW_File!K:K) -> 0 | H1772: =SUMIF(RAW_File!D:D,C:C,RAW_File!M:M) -> 0 | I1772: =ABS(G1772-H1772) -> 0

Sheet Summary
A1: Report Till-19/01/2026
A2: Sales Report - 05:50 PM
A3: DSO NO | B3: DSO NAME | C3: UDDOKTA | D3: Till-B2BS | E3: Till-B2BR | F3: Till Day CI | G3: Till Day CO | H3: Till Txn | I3: BALANCE
A4: 01334764529 | B4: AJHARUL | C4: =COUNTIF(DSO!A:A,A4) -> 50 | D4: =SUMIF(RAW_File!C:C,A4,RAW_File!K:K) -> 80000 | E4: =SUMIF(RAW_File!C:C,A4,RAW_File!M:M) -> 505000 | F4: =SUMIF(RAW_File!C:C,A4,RAW_File!G:G) -> 105980 | G4: =SUMIF(RAW_File!C:C,A4,RAW_File!H:H) -> 352108 | H4: =SUMIF(RAW_File!C:C,A4,RAW_File!I:I) -> 458088 | I4: =SUMIF(RAW_File!C:C,A4,RAW_File!F:F) -> 367958.25
A5: 01334764530 | B5: MD. ANZARUL ISLAM | C5: =COUNTIF(DSO!A:A,A5) -> 50 | D5: =SUMIF(RAW_File!C:C,A5,RAW_File!K:K) -> 147000 | E5: =SUMIF(RAW_File!C:C,A5,RAW_File!M:M) -> 620000 | F5: =SUMIF(RAW_File!C:C,A5,RAW_File!G:G) -> 180171 | G5: =SUMIF(RAW_File!C:C,A5,RAW_File!H:H) -> 469144 | H5: =SUMIF(RAW_File!C:C,A5,RAW_File!I:I) -> 649315 | I5: =SUMIF(RAW_File!C:C,A5,RAW_File!F:F) -> 302521.13
A6: 01334764531 | B6: MONI BHUSION ROY | C6: =COUNTIF(DSO!A:A,A6) -> 48 | D6: =SUMIF(RAW_File!C:C,A6,RAW_File!K:K) -> 201000 | E6: =SUMIF(RAW_File!C:C,A6,RAW_File!M:M) -> 481000 | F6: =SUMIF(RAW_File!C:C,A6,RAW_File!G:G) -> 136915 | G6: =SUMIF(RAW_File!C:C,A6,RAW_File!H:H) -> 360495 | H6: =SUMIF(RAW_File!C:C,A6,RAW_File!I:I) -> 497410 | I6: =SUMIF(RAW_File!C:C,A6,RAW_File!F:F) -> 396608.09
A7: 01334764532 | B7: MD. MIRAJUL ISLAM | C7: =COUNTIF(DSO!A:A,A7) -> 52 | D7: =SUMIF(RAW_File!C:C,A7,RAW_File!K:K) -> 227000 | E7: =SUMIF(RAW_File!C:C,A7,RAW_File!M:M) -> 700000 | F7: =SUMIF(RAW_File!C:C,A7,RAW_File!G:G) -> 224255 | G7: =SUMIF(RAW_File!C:C,A7,RAW_File!H:H) -> 507918 | H7: =SUMIF(RAW_File!C:C,A7,RAW_File!I:I) -> 732173 | I7: =SUMIF(RAW_File!C:C,A7,RAW_File!F:F) -> 644796.9
A8: 01334764533 | B8: SUJAN SARKERR | C8: =COUNTIF(DSO!A:A,A8) -> 48 | D8: =SUMIF(RAW_File!C:C,A8,RAW_File!K:K) -> 98000 | E8: =SUMIF(RAW_File!C:C,A8,RAW_File!M:M) -> 777000 | F8: =SUMIF(RAW_File!C:C,A8,RAW_File!G:G) -> 290359 | G8: =SUMIF(RAW_File!C:C,A8,RAW_File!H:H) -> 535900.27 | H8: =SUMIF(RAW_File!C:C,A8,RAW_File!I:I) -> 826259.27 | I8: =SUMIF(RAW_File!C:C,A8,RAW_File!F:F) -> 605693.66
A9: 01334764535 | B9: MOSIUR RAHMAN | C9: =COUNTIF(DSO!A:A,A9) -> 51 | D9: =SUMIF(RAW_File!C:C,A9,RAW_File!K:K) -> 127000 | E9: =SUMIF(RAW_File!C:C,A9,RAW_File!M:M) -> 823000 | F9: =SUMIF(RAW_File!C:C,A9,RAW_File!G:G) -> 149558 | G9: =SUMIF(RAW_File!C:C,A9,RAW_File!H:H) -> 583504 | H9: =SUMIF(RAW_File!C:C,A9,RAW_File!I:I) -> 733062 | I9: =SUMIF(RAW_File!C:C,A9,RAW_File!F:F) -> 345301.32
A10: 01334764536 | B10: MD. JAMAL ISLAM | C10: =COUNTIF(DSO!A:A,A10) -> 50 | D10: =SUMIF(RAW_File!C:C,A10,RAW_File!K:K) -> 250500 | E10: =SUMIF(RAW_File!C:C,A10,RAW_File!M:M) -> 700500 | F10: =SUMIF(RAW_File!C:C,A10,RAW_File!G:G) -> 326384 | G10: =SUMIF(RAW_File!C:C,A10,RAW_File!H:H) -> 700798 | H10: =SUMIF(RAW_File!C:C,A10,RAW_File!I:I) -> 1027182 | I10: =SUMIF(RAW_File!C:C,A10,RAW_File!F:F) -> 368505.86
A11: 01334764538 | B11: UTTAM ROY | C11: =COUNTIF(DSO!A:A,A11) -> 50 | D11: =SUMIF(RAW_File!C:C,A11,RAW_File!K:K) -> 109000 | E11: =SUMIF(RAW_File!C:C,A11,RAW_File!M:M) -> 994000 | F11: =SUMIF(RAW_File!C:C,A11,RAW_File!G:G) -> 121322 | G11: =SUMIF(RAW_File!C:C,A11,RAW_File!H:H) -> 649413 | H11: =SUMIF(RAW_File!C:C,A11,RAW_File!I:I) -> 770735 | I11: =SUMIF(RAW_File!C:C,A11,RAW_File!F:F) -> 365025.18
A12: SUMON RAY-8 | C12: =SUM(C4:C11) -> 399 | D12: =SUM(D4:D11) -> 1239500 | E12: =SUM(E4:E11) -> 5600500 | F12: =SUM(F4:F11) -> 1534944 | G12: =SUM(G4:G11) -> 4159280.3 | H12: =SUM(H4:H11) -> 5694224.3 | I12: =SUM(I4:I11) -> 3396410.4
A13: 01334764509 | B13: MD. SUMON RAHMAN | C13: =COUNTIF(DSO!A:A,A13) -> 42 | D13: =SUMIF(RAW_File!C:C,A13,RAW_File!K:K) -> 196000 | E13: =SUMIF(RAW_File!C:C,A13,RAW_File!M:M) -> 290000 | F13: =SUMIF(RAW_File!C:C,A13,RAW_File!G:G) -> 325458 | G13: =SUMIF(RAW_File!C:C,A13,RAW_File!H:H) -> 332414 | H13: =SUMIF(RAW_File!C:C,A13,RAW_File!I:I) -> 657872 | I13: =SUMIF(RAW_File!C:C,A13,RAW_File!F:F) -> 517773.55
A14: 01334764510 | B14: ASBI KARIM | C14: =COUNTIF(DSO!A:A,A14) -> 47 | D14: =SUMIF(RAW_File!C:C,A14,RAW_File!K:K) -> 482000 | E14: =SUMIF(RAW_File!C:C,A14,RAW_File!M:M) -> 535000 | F14: =SUMIF(RAW_File!C:C,A14,RAW_File!G:G) -> 650418 | G14: =SUMIF(RAW_File!C:C,A14,RAW_File!H:H) -> 704716 | H14: =SUMIF(RAW_File!C:C,A14,RAW_File!I:I) -> 1355134 | I14: =SUMIF(RAW_File!C:C,A14,RAW_File!F:F) -> 602914.45
A15: 01334764511 | B15: MD. RUHUL AMIN | C15: =COUNTIF(DSO!A:A,A15) -> 45 | D15: =SUMIF(RAW_File!C:C,A15,RAW_File!K:K) -> 236000 | E15: =SUMIF(RAW_File!C:C,A15,RAW_File!M:M) -> 532000 | F15: =SUMIF(RAW_File!C:C,A15,RAW_File!G:G) -> 297408 | G15: =SUMIF(RAW_File!C:C,A15,RAW_File!H:H) -> 552583 | H15: =SUMIF(RAW_File!C:C,A15,RAW_File!I:I) -> 849991 | I15: =SUMIF(RAW_File!C:C,A15,RAW_File!F:F) -> 433260.74
A16: 01334764512 | B16: PRODESH CHANDRO ROY | C16: =COUNTIF(DSO!A:A,A16) -> 44 | D16: =SUMIF(RAW_File!C:C,A16,RAW_File!K:K) -> 150000 | E16: =SUMIF(RAW_File!C:C,A16,RAW_File!M:M) -> 360000 | F16: =SUMIF(RAW_File!C:C,A16,RAW_File!G:G) -> 144411 | G16: =SUMIF(RAW_File!C:C,A16,RAW_File!H:H) -> 280929 | H16: =SUMIF(RAW_File!C:C,A16,RAW_File!I:I) -> 425340 | I16: =SUMIF(RAW_File!C:C,A16,RAW_File!F:F) -> 238475.9
A17: 01334764513 | B17: SELIM SAZZAD | C17: =COUNTIF(DSO!A:A,A17) -> 46 | D17: =SUMIF(RAW_File!C:C,A17,RAW_File!K:K) -> 270000 | E17: =SUMIF(RAW_File!C:C,A17,RAW_File!M:M) -> 483000 | F17: =SUMIF(RAW_File!C:C,A17,RAW_File!G:G) -> 416646 | G17: =SUMIF(RAW_File!C:C,A17,RAW_File!H:H) -> 493252 | H17: =SUMIF(RAW_File!C:C,A17,RAW_File!I:I) -> 909898 | I17: =SUMIF(RAW_File!C:C,A17,RAW_File!F:F) -> 621699.87
A18: 01334764514 | B18: MD. SAZZADUL ISLAM SOHAG | C18: =COUNTIF(DSO!A:A,A18) -> 45 | D18: =SUMIF(RAW_File!C:C,A18,RAW_File!K:K) -> 247000 | E18: =SUMIF(RAW_File!C:C,A18,RAW_File!M:M) -> 229000 | F18: =SUMIF(RAW_File!C:C,A18,RAW_File!G:G) -> 444172.6 | G18: =SUMIF(RAW_File!C:C,A18,RAW_File!H:H) -> 390872 | H18: =SUMIF(RAW_File!C:C,A18,RAW_File!I:I) -> 835044.6 | I18: =SUMIF(RAW_File!C:C,A18,RAW_File!F:F) -> 772405.1
A19: 01334764515 | B19: MD. ABDUL MANNAN | C19: =COUNTIF(DSO!A:A,A19) -> 42 | D19: =SUMIF(RAW_File!C:C,A19,RAW_File!K:K) -> 222000 | E19: =SUMIF(RAW_File!C:C,A19,RAW_File!M:M) -> 263000 | F19: =SUMIF(RAW_File!C:C,A19,RAW_File!G:G) -> 271357 | G19: =SUMIF(RAW_File!C:C,A19,RAW_File!H:H) -> 377317 | H19: =SUMIF(RAW_File!C:C,A19,RAW_File!I:I) -> 648674 | I19: =SUMIF(RAW_File!C:C,A19,RAW_File!F:F) -> 580465.68
A20: 01334764516 | B20: SAZZAD ISLAM | C20: =COUNTIF(DSO!A:A,A20) -> 43 | D20: =SUMIF(RAW_File!C:C,A20,RAW_File!K:K) -> 250000 | E20: =SUMIF(RAW_File!C:C,A20,RAW_File!M:M) -> 294000 | F20: =SUMIF(RAW_File!C:C,A20,RAW_File!G:G) -> 351509 | G20: =SUMIF(RAW_File!C:C,A20,RAW_File!H:H) -> 481531 | H20: =SUMIF(RAW_File!C:C,A20,RAW_File!I:I) -> 833040 | I20: =SUMIF(RAW_File!C:C,A20,RAW_File!F:F) -> 487855.1
A21: 01334764517 | B21: GOPEN CHANDRO ROY | C21: =COUNTIF(DSO!A:A,A21) -> 50 | D21: =SUMIF(RAW_File!C:C,A21,RAW_File!K:K) -> 224000 | E21: =SUMIF(RAW_File!C:C,A21,RAW_File!M:M) -> 505000 | F21: =SUMIF(RAW_File!C:C,A21,RAW_File!G:G) -> 353210 | G21: =SUMIF(RAW_File!C:C,A21,RAW_File!H:H) -> 511047 | H21: =SUMIF(RAW_File!C:C,A21,RAW_File!I:I) -> 864257 | I21: =SUMIF(RAW_File!C:C,A21,RAW_File!F:F) -> 308165.12
A22: 01334764534 | B22: ARUN ROY | C22: =COUNTIF(DSO!A:A,A22) -> 50 | D22: =SUMIF(RAW_File!C:C,A22,RAW_File!K:K) -> 79000 | E22: =SUMIF(RAW_File!C:C,A22,RAW_File!M:M) -> 730950 | F22: =SUMIF(RAW_File!C:C,A22,RAW_File!G:G) -> 121460 | G22: =SUMIF(RAW_File!C:C,A22,RAW_File!H:H) -> 517304 | H22: =SUMIF(RAW_File!C:C,A22,RAW_File!I:I) -> 638764 | I22: =SUMIF(RAW_File!C:C,A22,RAW_File!F:F) -> 198263.14
A23: MD. REJAUL ISLAM-10 | C23: =SUM(C13:C22) -> 454 | D23: =SUM(D13:D22) -> 2356000 | E23: =SUM(E13:E22) -> 4221950 | F23: =SUM(F13:F22) -> 3376049.6 | G23: =SUM(G13:G22) -> 4641965 | H23: =SUM(H13:H22) -> 8018014.6 | I23: =SUM(I13:I22) -> 4761278.6
A24: 01334764519 | B24: BABUL CHANDRO ROY | C24: =COUNTIF(DSO!A:A,A24) -> 44 | D24: =SUMIF(RAW_File!C:C,A24,RAW_File!K:K) -> 148000 | E24: =SUMIF(RAW_File!C:C,A24,RAW_File!M:M) -> 659000 | F24: =SUMIF(RAW_File!C:C,A24,RAW_File!G:G) -> 260298 | G24: =SUMIF(RAW_File!C:C,A24,RAW_File!H:H) -> 547378 | H24: =SUMIF(RAW_File!C:C,A24,RAW_File!I:I) -> 807676 | I24: =SUMIF(RAW_File!C:C,A24,RAW_File!F:F) -> 395297.05
A25: 01334764520 | B25: TONOY SINGHA ROY | C25: =COUNTIF(DSO!A:A,A25) -> 47 | D25: =SUMIF(RAW_File!C:C,A25,RAW_File!K:K) -> 164000 | E25: =SUMIF(RAW_File!C:C,A25,RAW_File!M:M) -> 429500 | F25: =SUMIF(RAW_File!C:C,A25,RAW_File!G:G) -> 219747 | G25: =SUMIF(RAW_File!C:C,A25,RAW_File!H:H) -> 329900.55 | H25: =SUMIF(RAW_File!C:C,A25,RAW_File!I:I) -> 549647.55 | I25: =SUMIF(RAW_File!C:C,A25,RAW_File!F:F) -> 407551.69
A26: 01334764521 | B26: ABDUL MAJED | C26: =COUNTIF(DSO!A:A,A26) -> 38 | D26: =SUMIF(RAW_File!C:C,A26,RAW_File!K:K) -> 165500 | E26: =SUMIF(RAW_File!C:C,A26,RAW_File!M:M) -> 269000 | F26: =SUMIF(RAW_File!C:C,A26,RAW_File!G:G) -> 485931 | G26: =SUMIF(RAW_File!C:C,A26,RAW_File!H:H) -> 504584 | H26: =SUMIF(RAW_File!C:C,A26,RAW_File!I:I) -> 990515 | I26: =SUMIF(RAW_File!C:C,A26,RAW_File!F:F) -> 283420.01
A27: 01334764522 | B27: PITUS ROY | C27: =COUNTIF(DSO!A:A,A27) -> 45 | D27: =SUMIF(RAW_File!C:C,A27,RAW_File!K:K) -> 224000 | E27: =SUMIF(RAW_File!C:C,A27,RAW_File!M:M) -> 663000 | F27: =SUMIF(RAW_File!C:C,A27,RAW_File!G:G) -> 370843 | G27: =SUMIF(RAW_File!C:C,A27,RAW_File!H:H) -> 654056 | H27: =SUMIF(RAW_File!C:C,A27,RAW_File!I:I) -> 1024899 | I27: =SUMIF(RAW_File!C:C,A27,RAW_File!F:F) -> 649854.27
A28: 01334764523 | B28: SREE BINDABON CHANDRA | C28: =COUNTIF(DSO!A:A,A28) -> 51 | D28: =SUMIF(RAW_File!C:C,A28,RAW_File!K:K) -> 263000 | E28: =SUMIF(RAW_File!C:C,A28,RAW_File!M:M) -> 524000 | F28: =SUMIF(RAW_File!C:C,A28,RAW_File!G:G) -> 351450 | G28: =SUMIF(RAW_File!C:C,A28,RAW_File!H:H) -> 497566 | H28: =SUMIF(RAW_File!C:C,A28,RAW_File!I:I) -> 849016 | I28: =SUMIF(RAW_File!C:C,A28,RAW_File!F:F) -> 569887.18
A29: 01334764524 | B29: SREE JOTISH CHANDRO ROY | C29: =COUNTIF(DSO!A:A,A29) -> 43 | D29: =SUMIF(RAW_File!C:C,A29,RAW_File!K:K) -> 252000 | E29: =SUMIF(RAW_File!C:C,A29,RAW_File!M:M) -> 495000 | F29: =SUMIF(RAW_File!C:C,A29,RAW_File!G:G) -> 307279 | G29: =SUMIF(RAW_File!C:C,A29,RAW_File!H:H) -> 449988 | H29: =SUMIF(RAW_File!C:C,A29,RAW_File!I:I) -> 757267 | I29: =SUMIF(RAW_File!C:C,A29,RAW_File!F:F) -> 495194.16
A30: 01334764525 | B30: MD. GOLAM KIBRIA | C30: =COUNTIF(DSO!A:A,A30) -> 47 | D30: =SUMIF(RAW_File!C:C,A30,RAW_File!K:K) -> 134500 | E30: =SUMIF(RAW_File!C:C,A30,RAW_File!M:M) -> 539999 | F30: =SUMIF(RAW_File!C:C,A30,RAW_File!G:G) -> 154912 | G30: =SUMIF(RAW_File!C:C,A30,RAW_File!H:H) -> 401767 | H30: =SUMIF(RAW_File!C:C,A30,RAW_File!I:I) -> 556679 | I30: =SUMIF(RAW_File!C:C,A30,RAW_File!F:F) -> 333680.81
A31: 01334764526 | B31: NINTANONDO ROY | C31: =COUNTIF(DSO!A:A,A31) -> 47 | D31: =SUMIF(RAW_File!C:C,A31,RAW_File!K:K) -> 141000 | E31: =SUMIF(RAW_File!C:C,A31,RAW_File!M:M) -> 183000 | F31: =SUMIF(RAW_File!C:C,A31,RAW_File!G:G) -> 294481 | G31: =SUMIF(RAW_File!C:C,A31,RAW_File!H:H) -> 364570 | H31: =SUMIF(RAW_File!C:C,A31,RAW_File!I:I) -> 659051 | I31: =SUMIF(RAW_File!C:C,A31,RAW_File!F:F) -> 531534.25
A32: 01334764527 | B32: UTTOM KUMAR | C32: =COUNTIF(DSO!A:A,A32) -> 49 | D32: =SUMIF(RAW_File!C:C,A32,RAW_File!K:K) -> 77000 | E32: =SUMIF(RAW_File!C:C,A32,RAW_File!M:M) -> 533000 | F32: =SUMIF(RAW_File!C:C,A32,RAW_File!G:G) -> 132696 | G32: =SUMIF(RAW_File!C:C,A32,RAW_File!H:H) -> 322764 | H32: =SUMIF(RAW_File!C:C,A32,RAW_File!I:I) -> 455460 | I32: =SUMIF(RAW_File!C:C,A32,RAW_File!F:F) -> 192905.56
A33: 01334764528 | B33: MD. SHAHIN ISLAM | C33: =COUNTIF(DSO!A:A,A33) -> 47 | D33: =SUMIF(RAW_File!C:C,A33,RAW_File!K:K) -> 133000 | E33: =SUMIF(RAW_File!C:C,A33,RAW_File!M:M) -> 512000 | F33: =SUMIF(RAW_File!C:C,A33,RAW_File!G:G) -> 360273 | G33: =SUMIF(RAW_File!C:C,A33,RAW_File!H:H) -> 560514 | H33: =SUMIF(RAW_File!C:C,A33,RAW_File!I:I) -> 920787 | I33: =SUMIF(RAW_File!C:C,A33,RAW_File!F:F) -> 485710.94
A34: SATYENDRONATH ROY-10 | C34: =SUM(C24:C33) -> 458 | D34: =SUM(D24:D33) -> 1702000 | E34: =SUM(E24:E33) -> 4807499 | F34: =SUM(F24:F33) -> 2937910 | G34: =SUM(G24:G33) -> 4633087.5 | H34: =SUM(H24:H33) -> 7570997.5 | I34: =SUM(I24:I33) -> 4345035.9
A35: 01334764501 | B35: RIMON ROY | C35: =COUNTIF(DSO!A:A,A35) -> 42 | D35: =SUMIF(RAW_File!C:C,A35,RAW_File!K:K) -> 146000 | E35: =SUMIF(RAW_File!C:C,A35,RAW_File!M:M) -> 292000 | F35: =SUMIF(RAW_File!C:C,A35,RAW_File!G:G) -> 356260 | G35: =SUMIF(RAW_File!C:C,A35,RAW_File!H:H) -> 386754 | H35: =SUMIF(RAW_File!C:C,A35,RAW_File!I:I) -> 743014 | I35: =SUMIF(RAW_File!C:C,A35,RAW_File!F:F) -> 265561.16
A36: 01334764502 | B36: MD. EAMAN ALI | C36: =COUNTIF(DSO!A:A,A36) -> 49 | D36: =SUMIF(RAW_File!C:C,A36,RAW_File!K:K) -> 437000 | E36: =SUMIF(RAW_File!C:C,A36,RAW_File!M:M) -> 365000 | F36: =SUMIF(RAW_File!C:C,A36,RAW_File!G:G) -> 416960 | G36: =SUMIF(RAW_File!C:C,A36,RAW_File!H:H) -> 469827 | H36: =SUMIF(RAW_File!C:C,A36,RAW_File!I:I) -> 886787 | I36: =SUMIF(RAW_File!C:C,A36,RAW_File!F:F) -> 589922.45
A37: 01334764503 | B37: ABU MUSA | C37: =COUNTIF(DSO!A:A,A37) -> 51 | D37: =SUMIF(RAW_File!C:C,A37,RAW_File!K:K) -> 259000 | E37: =SUMIF(RAW_File!C:C,A37,RAW_File!M:M) -> 340000 | F37: =SUMIF(RAW_File!C:C,A37,RAW_File!G:G) -> 349036 | G37: =SUMIF(RAW_File!C:C,A37,RAW_File!H:H) -> 412805 | H37: =SUMIF(RAW_File!C:C,A37,RAW_File!I:I) -> 761841 | I37: =SUMIF(RAW_File!C:C,A37,RAW_File!F:F) -> 537137.5
A38: 01334764504 | B38: ABDUS SALAM | C38: =COUNTIF(DSO!A:A,A38) -> 42 | D38: =SUMIF(RAW_File!C:C,A38,RAW_File!K:K) -> 443000 | E38: =SUMIF(RAW_File!C:C,A38,RAW_File!M:M) -> 287000 | F38: =SUMIF(RAW_File!C:C,A38,RAW_File!G:G) -> 503125 | G38: =SUMIF(RAW_File!C:C,A38,RAW_File!H:H) -> 387144 | H38: =SUMIF(RAW_File!C:C,A38,RAW_File!I:I) -> 890269 | I38: =SUMIF(RAW_File!C:C,A38,RAW_File!F:F) -> 626644.16
A39: 01334764505 | B39: MD. ALAMIN ISLAM-2 | C39: =COUNTIF(DSO!A:A,A39) -> 54 | D39: =SUMIF(RAW_File!C:C,A39,RAW_File!K:K) -> 187000 | E39: =SUMIF(RAW_File!C:C,A39,RAW_File!M:M) -> 479500 | F39: =SUMIF(RAW_File!C:C,A39,RAW_File!G:G) -> 324022 | G39: =SUMIF(RAW_File!C:C,A39,RAW_File!H:H) -> 517054 | H39: =SUMIF(RAW_File!C:C,A39,RAW_File!I:I) -> 841076 | I39: =SUMIF(RAW_File!C:C,A39,RAW_File!F:F) -> 387002.99
A40: 01334764506 | B40: MD. ALAMIN ISLAM | C40: =COUNTIF(DSO!A:A,A40) -> 44 | D40: =SUMIF(RAW_File!C:C,A40,RAW_File!K:K) -> 93000 | E40: =SUMIF(RAW_File!C:C,A40,RAW_File!M:M) -> 562000 | F40: =SUMIF(RAW_File!C:C,A40,RAW_File!G:G) -> 249935 | G40: =SUMIF(RAW_File!C:C,A40,RAW_File!H:H) -> 200067 | H40: =SUMIF(RAW_File!C:C,A40,RAW_File!I:I) -> 450002 | I40: =SUMIF(RAW_File!C:C,A40,RAW_File!F:F) -> 368945.71
...

Sheet DSS Summary
A1: =Summary!A1:I1 -> Report Till-19/01/2026
A2: =Summary!A2:I2 -> Sales Report - 05:50 PM
A3: DSO NO | B3: DSO NAME | C3: UDDOKTA | D3: 1k-Balance Ach. | E3: % | F3: S-R=3k Ach. | G3: % | H3: R-S=2k | I3: % | J3: Total Strike | K3: %
A4: 01334764529 | B4: =VLOOKUP(A4,Summary!A4:B4,2,FALSE) -> AJHARUL | C4: =COUNTIF(DSO!A:A,A4) -> 50 | D4: =COUNTIFS(DSO!A:A,A4,DSO!D:D,">999") -> 40 | E4: =D4/C4 -> 0.8 | F4: =COUNTIFS(RAW_File!C:C,A4:A11,RAW_File!N:N,">2999") -> 9 | G4: =F4/C4 -> 0.18 | H4: =COUNTIFS(RAW_File!C:C,A4:A11,RAW_File!O:O,">1999") -> 35 | I4: =H4/C4 -> 0.7 | J4: =F4+H4 -> 44 | K4: =J4/C4 -> 0.88
A5: 01334764530 | B5: =VLOOKUP(A5,Summary!A5:B5,2,FALSE) -> MD. ANZARUL ISLAM | C5: =COUNTIF(DSO!A:A,A5) -> 50 | D5: =COUNTIFS(DSO!A:A,A5,DSO!D:D,">999") -> 33 | E5: =D5/C5 -> 0.66 | F5: =COUNTIFS(RAW_File!C:C,A5:A12,RAW_File!N:N,">2999") -> 15 | G5: =F5/C5 -> 0.3 | H5: =COUNTIFS(RAW_File!C:C,A5:A12,RAW_File!O:O,">1999") -> 24 | I5: =H5/C5 -> 0.48 | J5: =F5+H5 -> 39 | K5: =J5/C5 -> 0.78
A6: 01334764531 | B6: =VLOOKUP(A6,Summary!A6:B6,2,FALSE) -> MONI BHUSION ROY | C6: =COUNTIF(DSO!A:A,A6) -> 48 | D6: =COUNTIFS(DSO!A:A,A6,DSO!D:D,">999") -> 29 | E6: =D6/C6 -> 0.60416667 | F6: =COUNTIFS(RAW_File!C:C,A6:A13,RAW_File!N:N,">2999") -> 17 | G6: =F6/C6 -> 0.35416667 | H6: =COUNTIFS(RAW_File!C:C,A6:A13,RAW_File!O:O,">1999") -> 25 | I6: =H6/C6 -> 0.52083333 | J6: =F6+H6 -> 42 | K6: =J6/C6 -> 0.875
A7: 01334764532 | B7: =VLOOKUP(A7,Summary!A7:B7,2,FALSE) -> MD. MIRAJUL ISLAM | C7: =COUNTIF(DSO!A:A,A7) -> 52 | D7: =COUNTIFS(DSO!A:A,A7,DSO!D:D,">999") -> 40 | E7: =D7/C7 -> 0.76923077 | F7: =COUNTIFS(RAW_File!C:C,A7:A14,RAW_File!N:N,">2999") -> 19 | G7: =F7/C7 -> 0.36538462 | H7: =COUNTIFS(RAW_File!C:C,A7:A14,RAW_File!O:O,">1999") -> 28 | I7: =H7/C7 -> 0.53846154 | J7: =F7+H7 -> 47 | K7: =J7/C7 -> 0.90384615
A8: 01334764533 | B8: =VLOOKUP(A8,Summary!A8:B8,2,FALSE) -> SUJAN SARKERR | C8: =COUNTIF(DSO!A:A,A8) -> 48 | D8: =COUNTIFS(DSO!A:A,A8,DSO!D:D,">999") -> 38 | E8: =D8/C8 -> 0.79166667 | F8: =COUNTIFS(RAW_File!C:C,A8:A15,RAW_File!N:N,">2999") -> 13 | G8: =F8/C8 -> 0.27083333 | H8: =COUNTIFS(RAW_File!C:C,A8:A15,RAW_File!O:O,">1999") -> 30 | I8: =H8/C8 -> 0.625 | J8: =F8+H8 -> 43 | K8: =J8/C8 -> 0.89583333
A9: 01334764535 | B9: =VLOOKUP(A9,Summary!A9:B9,2,FALSE) -> MOSIUR RAHMAN | C9: =COUNTIF(DSO!A:A,A9) -> 51 | D9: =COUNTIFS(DSO!A:A,A9,DSO!D:D,">999") -> 40 | E9: =D9/C9 -> 0.78431373 | F9: =COUNTIFS(RAW_File!C:C,A9:A16,RAW_File!N:N,">2999") -> 11 | G9: =F9/C9 -> 0.21568627 | H9: =COUNTIFS(RAW_File!C:C,A9:A16,RAW_File!O:O,">1999") -> 29 | I9: =H9/C9 -> 0.56862745 | J9: =F9+H9 -> 40 | K9: =J9/C9 -> 0.78431373
A10: 01334764536 | B10: =VLOOKUP(A10,Summary!A10:B10,2,FALSE) -> MD. JAMAL ISLAM | C10: =COUNTIF(DSO!A:A,A10) -> 50 | D10: =COUNTIFS(DSO!A:A,A10,DSO!D:D,">999") -> 33 | E10: =D10/C10 -> 0.66 | F10: =COUNTIFS(RAW_File!C:C,A10:A17,RAW_File!N:N,">2999") -> 14 | G10: =F10/C10 -> 0.28 | H10: =COUNTIFS(RAW_File!C:C,A10:A17,RAW_File!O:O,">1999") -> 27 | I10: =H10/C10 -> 0.54 | J10: =F10+H10 -> 41 | K10: =J10/C10 -> 0.82
A11: 01334764538 | B11: =VLOOKUP(A11,Summary!A11:B11,2,FALSE) -> UTTAM ROY | C11: =COUNTIF(DSO!A:A,A11) -> 50 | D11: =COUNTIFS(DSO!A:A,A11,DSO!D:D,">999") -> 37 | E11: =D11/C11 -> 0.74 | F11: =COUNTIFS(RAW_File!C:C,A11:A17,RAW_File!N:N,">2999") -> 9 | G11: =F11/C11 -> 0.18 | H11: =COUNTIFS(RAW_File!C:C,A11:A17,RAW_File!O:O,">1999") -> 33 | I11: =H11/C11 -> 0.66 | J11: =F11+H11 -> 42 | K11: =J11/C11 -> 0.84
A12: SUMON RAY-8 | C12: =SUM(C4:C11) -> 399 | D12: =SUM(D4:D11) -> 290 | E12: =D12/C12 -> 0.72681704 | F12: =SUM(F4:F11) -> 107 | G12: =F12/C12 -> 0.26817043 | H12: =SUM(H4:H11) -> 231 | I12: =H12/C12 -> 0.57894737 | J12: =SUM(J4:J11) -> 338 | K12: =J12/C12 -> 0.84711779
A13: 01334764509 | B13: =VLOOKUP(A13,Summary!A13:B13,2,FALSE) -> MD. SUMON RAHMAN | C13: =COUNTIF(DSO!A:A,A13) -> 42 | D13: =COUNTIFS(DSO!A:A,A13,DSO!D:D,">999") -> 30 | E13: =D13/C13 -> 0.71428571 | F13: =COUNTIFS(RAW_File!C:C,A13:A22,RAW_File!N:N,">2999") -> 16 | G13: =F13/C13 -> 0.38095238 | H13: =COUNTIFS(RAW_File!C:C,A13:A22,RAW_File!O:O,">1999") -> 20 | I13: =H13/C13 -> 0.47619048 | J13: =F13+H13 -> 36 | K13: =J13/C13 -> 0.85714286
A14: 01334764510 | B14: =VLOOKUP(A14,Summary!A14:B14,2,FALSE) -> ASBI KARIM | C14: =COUNTIF(DSO!A:A,A14) -> 47 | D14: =COUNTIFS(DSO!A:A,A14,DSO!D:D,">999") -> 31 | E14: =D14/C14 -> 0.65957447 | F14: =COUNTIFS(RAW_File!C:C,A14:A23,RAW_File!N:N,">2999") -> 26 | G14: =F14/C14 -> 0.55319149 | H14: =COUNTIFS(RAW_File!C:C,A14:A23,RAW_File!O:O,">1999") -> 17 | I14: =H14/C14 -> 0.36170213 | J14: =F14+H14 -> 43 | K14: =J14/C14 -> 0.91489362
A15: 01334764511 | B15: =VLOOKUP(A15,Summary!A15:B15,2,FALSE) -> MD. RUHUL AMIN | C15: =COUNTIF(DSO!A:A,A15) -> 45 | D15: =COUNTIFS(DSO!A:A,A15,DSO!D:D,">999") -> 41 | E15: =D15/C15 -> 0.91111111 | F15: =COUNTIFS(RAW_File!C:C,A15:A24,RAW_File!N:N,">2999") -> 21 | G15: =F15/C15 -> 0.46666667 | H15: =COUNTIFS(RAW_File!C:C,A15:A24,RAW_File!O:O,">1999") -> 23 | I15: =H15/C15 -> 0.51111111 | J15: =F15+H15 -> 44 | K15: =J15/C15 -> 0.97777778
A16: 01334764512 | B16: =VLOOKUP(A16,Summary!A16:B16,2,FALSE) -> PRODESH CHANDRO ROY | C16: =COUNTIF(DSO!A:A,A16) -> 44 | D16: =COUNTIFS(DSO!A:A,A16,DSO!D:D,">999") -> 32 | E16: =D16/C16 -> 0.72727273 | F16: =COUNTIFS(RAW_File!C:C,A16:A25,RAW_File!N:N,">2999") -> 19 | G16: =F16/C16 -> 0.43181818 | H16: =COUNTIFS(RAW_File!C:C,A16:A25,RAW_File!O:O,">1999") -> 23 | I16: =H16/C16 -> 0.52272727 | J16: =F16+H16 -> 42 | K16: =J16/C16 -> 0.95454545
A17: 01334764513 | B17: =VLOOKUP(A17,Summary!A17:B17,2,FALSE) -> SELIM SAZZAD | C17: =COUNTIF(DSO!A:A,A17) -> 46 | D17: =COUNTIFS(DSO!A:A,A17,DSO!D:D,">999") -> 37 | E17: =D17/C17 -> 0.80434783 | F17: =COUNTIFS(RAW_File!C:C,A17:A26,RAW_File!N:N,">2999") -> 17 | G17: =F17/C17 -> 0.36956522 | H17: =COUNTIFS(RAW_File!C:C,A17:A26,RAW_File!O:O,">1999") -> 23 | I17: =H17/C17 -> 0.5 | J17: =F17+H17 -> 40 | K17: =J17/C17 -> 0.86956522
A18: 01334764514 | B18: =VLOOKUP(A18,Summary!A18:B18,2,FALSE) -> MD. SAZZADUL ISLAM SOHAG | C18: =COUNTIF(DSO!A:A,A18) -> 45 | D18: =COUNTIFS(DSO!A:A,A18,DSO!D:D,">999") -> 38 | E18: =D18/C18 -> 0.84444444 | F18: =COUNTIFS(RAW_File!C:C,A18:A27,RAW_File!N:N,">2999") -> 23 | G18: =F18/C18 -> 0.51111111 | H18: =COUNTIFS(RAW_File!C:C,A18:A27,RAW_File!O:O,">1999") -> 16 | I18: =H18/C18 -> 0.35555556 | J18: =F18+H18 -> 39 | K18: =J18/C18 -> 0.86666667
A19: 01334764515 | B19: =VLOOKUP(A19,Summary!A19:B19,2,FALSE) -> MD. ABDUL MANNAN | C19: =COUNTIF(DSO!A:A,A19) -> 42 | D19: =COUNTIFS(DSO!A:A,A19,DSO!D:D,">999") -> 32 | E19: =D19/C19 -> 0.76190476 | F19: =COUNTIFS(RAW_File!C:C,A19:A28,RAW_File!N:N,">2999") -> 20 | G19: =F19/C19 -> 0.47619048 | H19: =COUNTIFS(RAW_File!C:C,A19:A28,RAW_File!O:O,">1999") -> 17 | I19: =H19/C19 -> 0.4047619 | J19: =F19+H19 -> 37 | K19: =J19/C19 -> 0.88095238
A20: 01334764516 | B20: =VLOOKUP(A20,Summary!A20:B20,2,FALSE) -> SAZZAD ISLAM | C20: =COUNTIF(DSO!A:A,A20) -> 43 | D20: =COUNTIFS(DSO!A:A,A20,DSO!D:D,">999") -> 31 | E20: =D20/C20 -> 0.72093023 | F20: =COUNTIFS(RAW_File!C:C,A20:A29,RAW_File!N:N,">2999") -> 18 | G20: =F20/C20 -> 0.41860465 | H20: =COUNTIFS(RAW_File!C:C,A20:A29,RAW_File!O:O,">1999") -> 19 | I20: =H20/C20 -> 0.44186047 | J20: =F20+H20 -> 37 | K20: =J20/C20 -> 0.86046512
A21: 01334764517 | B21: =VLOOKUP(A21,Summary!A21:B21,2,FALSE) -> GOPEN CHANDRO ROY | C21: =COUNTIF(DSO!A:A,A21) -> 50 | D21: =COUNTIFS(DSO!A:A,A21,DSO!D:D,">999") -> 35 | E21: =D21/C21 -> 0.7 | F21: =COUNTIFS(RAW_File!C:C,A21:A31,RAW_File!N:N,">2999") -> 17 | G21: =F21/C21 -> 0.34 | H21: =COUNTIFS(RAW_File!C:C,A21:A31,RAW_File!O:O,">1999") -> 25 | I21: =H21/C21 -> 0.5 | J21: =F21+H21 -> 42 | K21: =J21/C21 -> 0.84
A22: 01334764534 | B22: =VLOOKUP(A22,Summary!A22:B22,2,FALSE) -> ARUN ROY | C22: =COUNTIF(DSO!A:A,A22) -> 50 | D22: =COUNTIFS(DSO!A:A,A22,DSO!D:D,">999") -> 28 | E22: =D22/C22 -> 0.56 | F22: =COUNTIFS(RAW_File!C:C,A22:A32,RAW_File!N:N,">2999") -> 7 | G22: =F22/C22 -> 0.14 | H22: =COUNTIFS(RAW_File!C:C,A22:A32,RAW_File!O:O,">1999") -> 36 | I22: =H22/C22 -> 0.72 | J22: =F22+H22 -> 43 | K22: =J22/C22 -> 0.86
A23: MD. REJAUL ISLAM-10 | C23: =SUM(C13:C22) -> 454 | D23: =SUM(D13:D22) -> 335 | E23: =D23/C23 -> 0.73788546 | F23: =SUM(F13:F22) -> 184 | G23: =F23/C23 -> 0.40528634 | H23: =SUM(H13:H22) -> 219 | I23: =H23/C23 -> 0.48237885 | J23: =SUM(J13:J22) -> 403 | K23: =J23/C23 -> 0.8876652
A24: 01334764519 | B24: =VLOOKUP(A24,Summary!A24:B24,2,FALSE) -> BABUL CHANDRO ROY | C24: =COUNTIF(DSO!A:A,A24) -> 44 | D24: =COUNTIFS(DSO!A:A,A24,DSO!D:D,">999") -> 35 | E24: =D24/C24 -> 0.79545455 | F24: =COUNTIFS(RAW_File!C:C,A24:A33,RAW_File!N:N,">2999") -> 15 | G24: =F24/C24 -> 0.34090909 | H24: =COUNTIFS(RAW_File!C:C,A24:A33,RAW_File!O:O,">1999") -> 23 | I24: =H24/C24 -> 0.52272727 | J24: =F24+H24 -> 38 | K24: =J24/C24 -> 0.86363636
A25: 01334764520 | B25: =VLOOKUP(A25,Summary!A25:B25,2,FALSE) -> TONOY SINGHA ROY | C25: =COUNTIF(DSO!A:A,A25) -> 47 | D25: =COUNTIFS(DSO!A:A,A25,DSO!D:D,">999") -> 33 | E25: =D25/C25 -> 0.70212766 | F25: =COUNTIFS(RAW_File!C:C,A25:A34,RAW_File!N:N,">2999") -> 13 | G25: =F25/C25 -> 0.27659574 | H25: =COUNTIFS(RAW_File!C:C,A25:A34,RAW_File!O:O,">1999") -> 27 | I25: =H25/C25 -> 0.57446809 | J25: =F25+H25 -> 40 | K25: =J25/C25 -> 0.85106383
A26: 01334764521 | B26: =VLOOKUP(A26,Summary!A26:B26,2,FALSE) -> ABDUL MAJED | C26: =COUNTIF(DSO!A:A,A26) -> 38 | D26: =COUNTIFS(DSO!A:A,A26,DSO!D:D,">999") -> 30 | E26: =D26/C26 -> 0.78947368 | F26: =COUNTIFS(RAW_File!C:C,A26:A35,RAW_File!N:N,">2999") -> 19 | G26: =F26/C26 -> 0.5 | H26: =COUNTIFS(RAW_File!C:C,A26:A35,RAW_File!O:O,">1999") -> 14 | I26: =H26/C26 -> 0.36842105 | J26: =F26+H26 -> 33 | K26: =J26/C26 -> 0.86842105
A27: 01334764522 | B27: =VLOOKUP(A27,Summary!A27:B27,2,FALSE) -> PITUS ROY | C27: =COUNTIF(DSO!A:A,A27) -> 45 | D27: =COUNTIFS(DSO!A:A,A27,DSO!D:D,">999") -> 37 | E27: =D27/C27 -> 0.82222222 | F27: =COUNTIFS(RAW_File!C:C,A27:A36,RAW_File!N:N,">2999") -> 20 | G27: =F27/C27 -> 0.44444444 | H27: =COUNTIFS(RAW_File!C:C,A27:A36,RAW_File!O:O,">1999") -> 23 | I27: =H27/C27 -> 0.51111111 | J27: =F27+H27 -> 43 | K27: =J27/C27 -> 0.95555556
A28: 01334764523 | B28: =VLOOKUP(A28,Summary!A28:B28,2,FALSE) -> SREE BINDABON CHANDRA | C28: =COUNTIF(DSO!A:A,A28) -> 51 | D28: =COUNTIFS(DSO!A:A,A28,DSO!D:D,">999") -> 43 | E28: =D28/C28 -> 0.84313725 | F28: =COUNTIFS(RAW_File!C:C,A28:A37,RAW_File!N:N,">2999") -> 20 | G28: =F28/C28 -> 0.39215686 | H28: =COUNTIFS(RAW_File!C:C,A28:A37,RAW_File!O:O,">1999") -> 26 | I28: =H28/C28 -> 0.50980392 | J28: =F28+H28 -> 46 | K28: =J28/C28 -> 0.90196078
A29: 01334764524 | B29: =VLOOKUP(A29,Summary!A29:B29,2,FALSE) -> SREE JOTISH CHANDRO ROY | C29: =COUNTIF(DSO!A:A,A29) -> 43 | D29: =COUNTIFS(DSO!A:A,A29,DSO!D:D,">999") -> 32 | E29: =D29/C29 -> 0.74418605 | F29: =COUNTIFS(RAW_File!C:C,A29:A38,RAW_File!N:N,">2999") -> 18 | G29: =F29/C29 -> 0.41860465 | H29: =COUNTIFS(RAW_File!C:C,A29:A38,RAW_File!O:O,">1999") -> 19 | I29: =H29/C29 -> 0.44186047 | J29: =F29+H29 -> 37 | K29: =J29/C29 -> 0.86046512
A30: 01334764525 | B30: =VLOOKUP(A30,Summary!A30:B30,2,FALSE) -> MD. GOLAM KIBRIA | C30: =COUNTIF(DSO!A:A,A30) -> 47 | D30: =COUNTIFS(DSO!A:A,A30,DSO!D:D,">999") -> 37 | E30: =D30/C30 -> 0.78723404 | F30: =COUNTIFS(RAW_File!C:C,A30:A39,RAW_File!N:N,">2999") -> 15 | G30: =F30/C30 -> 0.31914894 | H30: =COUNTIFS(RAW_File!C:C,A30:A39,RAW_File!O:O,">1999") -> 27 | I30: =H30/C30 -> 0.57446809 | J30: =F30+H30 -> 42 | K30: =J30/C30 -> 0.89361702
A31: 01334764526 | B31: =VLOOKUP(A31,Summary!A31:B31,2,FALSE) -> NINTANONDO ROY | C31: =COUNTIF(DSO!A:A,A31) -> 47 | D31: =COUNTIFS(DSO!A:A,A31,DSO!D:D,">999") -> 38 | E31: =D31/C31 -> 0.80851064 | F31: =COUNTIFS(RAW_File!C:C,A31:A40,RAW_File!N:N,">2999") -> 21 | G31: =F31/C31 -> 0.44680851 | H31: =COUNTIFS(RAW_File!C:C,A31:A40,RAW_File!O:O,">1999") -> 13 | I31: =H31/C31 -> 0.27659574 | J31: =F31+H31 -> 34 | K31: =J31/C31 -> 0.72340426
A32: 01334764527 | B32: =VLOOKUP(A32,Summary!A32:B32,2,FALSE) -> UTTOM KUMAR | C32: =COUNTIF(DSO!A:A,A32) -> 49 | D32: =COUNTIFS(DSO!A:A,A32,DSO!D:D,">999") -> 29 | E32: =D32/C32 -> 0.59183673 | F32: =COUNTIFS(RAW_File!C:C,A32:A40,RAW_File!N:N,">2999") -> 8 | G32: =F32/C32 -> 0.16326531 | H32: =COUNTIFS(RAW_File!C:C,A32:A40,RAW_File!O:O,">1999") -> 31 | I32: =H32/C32 -> 0.63265306 | J32: =F32+H32 -> 39 | K32: =J32/C32 -> 0.79591837
A33: 01334764528 | B33: =VLOOKUP(A33,Summary!A33:B33,2,FALSE) -> MD. SHAHIN ISLAM | C33: =COUNTIF(DSO!A:A,A33) -> 47 | D33: =COUNTIFS(DSO!A:A,A33,DSO!D:D,">999") -> 34 | E33: =D33/C33 -> 0.72340426 | F33: =COUNTIFS(RAW_File!C:C,A33:A41,RAW_File!N:N,">2999") -> 9 | G33: =F33/C33 -> 0.19148936 | H33: =COUNTIFS(RAW_File!C:C,A33:A41,RAW_File!O:O,">1999") -> 27 | I33: =H33/C33 -> 0.57446809 | J33: =F33+H33 -> 36 | K33: =J33/C33 -> 0.76595745
A34: SATYENDRONATH ROY-10 | C34: =SUM(C24:C33) -> 458 | D34: =SUM(D24:D33) -> 348 | E34: =D34/C34 -> 0.75982533 | F34: =SUM(F24:F33) -> 158 | G34: =F34/C34 -> 0.34497817 | H34: =SUM(H24:H33) -> 230 | I34: =H34/C34 -> 0.50218341 | J34: =SUM(J24:J33) -> 388 | K34: =J34/C34 -> 0.84716157
A35: 01334764501 | B35: =VLOOKUP(A35,Summary!A35:B35,2,FALSE) -> RIMON ROY | C35: =COUNTIF(DSO!A:A,A35) -> 42 | D35: =COUNTIFS(DSO!A:A,A35,DSO!D:D,">999") -> 26 | E35: =D35/C35 -> 0.61904762 | F35: =COUNTIFS(RAW_File!C:C,A35:A50,RAW_File!N:N,">2999") -> 17 | G35: =F35/C35 -> 0.4047619 | H35: =COUNTIFS(RAW_File!C:C,A35:A50,RAW_File!O:O,">1999") -> 18 | I35: =H35/C35 -> 0.42857143 | J35: =F35+H35 -> 35 | K35: =J35/C35 -> 0.83333333
A36: 01334764502 | B36: =VLOOKUP(A36,Summary!A36:B36,2,FALSE) -> MD. EAMAN ALI | C36: =COUNTIF(DSO!A:A,A36) -> 49 | D36: =COUNTIFS(DSO!A:A,A36,DSO!D:D,">999") -> 40 | E36: =D36/C36 -> 0.81632653 | F36: =COUNTIFS(RAW_File!C:C,A36:A51,RAW_File!N:N,">2999") -> 27 | G36: =F36/C36 -> 0.55102041 | H36: =COUNTIFS(RAW_File!C:C,A36:A51,RAW_File!O:O,">1999") -> 19 | I36: =H36/C36 -> 0.3877551 | J36: =F36+H36 -> 46 | K36: =J36/C36 -> 0.93877551
A37: 01334764503 | B37: =VLOOKUP(A37,Summary!A37:B37,2,FALSE) -> ABU MUSA | C37: =COUNTIF(DSO!A:A,A37) -> 51 | D37: =COUNTIFS(DSO!A:A,A37,DSO!D:D,">999") -> 41 | E37: =D37/C37 -> 0.80392157 | F37: =COUNTIFS(RAW_File!C:C,A37:A52,RAW_File!N:N,">2999") -> 29 | G37: =F37/C37 -> 0.56862745 | H37: =COUNTIFS(RAW_File!C:C,A37:A52,RAW_File!O:O,">1999") -> 17 | I37: =H37/C37 -> 0.33333333 | J37: =F37+H37 -> 46 | K37: =J37/C37 -> 0.90196078
A38: 01334764504 | B38: =VLOOKUP(A38,Summary!A38:B38,2,FALSE) -> ABDUS SALAM | C38: =COUNTIF(DSO!A:A,A38) -> 42 | D38: =COUNTIFS(DSO!A:A,A38,DSO!D:D,">999") -> 36 | E38: =D38/C38 -> 0.85714286 | F38: =COUNTIFS(RAW_File!C:C,A38:A53,RAW_File!N:N,">2999") -> 26 | G38: =F38/C38 -> 0.61904762 | H38: =COUNTIFS(RAW_File!C:C,A38:A53,RAW_File!O:O,">1999") -> 10 | I38: =H38/C38 -> 0.23809524 | J38: =F38+H38 -> 36 | K38: =J38/C38 -> 0.85714286
A39: 01334764505 | B39: =VLOOKUP(A39,Summary!A39:B39,2,FALSE) -> MD. ALAMIN ISLAM-2 | C39: =COUNTIF(DSO!A:A,A39) -> 54 | D39: =COUNTIFS(DSO!A:A,A39,DSO!D:D,">999") -> 32 | E39: =D39/C39 -> 0.59259259 | F39: =COUNTIFS(RAW_File!C:C,A39:A54,RAW_File!N:N,">2999") -> 18 | G39: =F39/C39 -> 0.33333333 | H39: =COUNTIFS(RAW_File!C:C,A39:A54,RAW_File!O:O,">1999") -> 24 | I39: =H39/C39 -> 0.44444444 | J39: =F39+H39 -> 42 | K39: =J39/C39 -> 0.77777778
A40: 01334764506 | B40: =VLOOKUP(A40,Summary!A40:B40,2,FALSE) -> MD. ALAMIN ISLAM | C40: =COUNTIF(DSO!A:A,A40) -> 44 | D40: =COUNTIFS(DSO!A:A,A40,DSO!D:D,">999") -> 25 | E40: =D40/C40 -> 0.56818182 | F40: =COUNTIFS(RAW_File!C:C,A40:A56,RAW_File!N:N,">2999") -> 14 | G40: =F40/C40 -> 0.31818182 | H40: =COUNTIFS(RAW_File!C:C,A40:A56,RAW_File!O:O,">1999") -> 22 | I40: =H40/C40 -> 0.5 | J40: =F40+H40 -> 36 | K40: =J40/C40 -> 0.81818182
...

Sheet RAW_File
A1: DHWALLET | B1: DHNAME | C1: DSO | D1: AGENT | E1: AGENTNAME | F1: BALANCE | G1: CASH_IN | H1: CASH_OUT | I1: TOTAL_TXN | J1: B2BS_CNT | K1: B2BS_AMT | L1: B2BR_CNT | M1: B2BR_AMT | N1: S | O1: R
A2: 01324142342 | B2: M/S. Sourav Traders | C2: 01334764538 | D2: 01344733073 | E2: ALVI IT SERVICE AND STUDIO | F2: 1069.9267 | G2: 255 | H2: 0 | I2: 255 | J2: 0 | K2: 0 | L2: 1 | M2: 5000 | N2: =K2-M2 -> -5000 | O2: =M2-K2 -> 5000
A3: 01324142342 | B3: M/S. Sourav Traders | C3: 01334764511 | D3: 01321011411 | E3: Ms/ Masfi Traders | F3: 11356.111 | G3: 3120 | H3: 63718 | I3: 66838 | J3: 1 | K3: 10000 | L3: 2 | M3: 60000 | N3: =K3-M3 -> -50000 | O3: =M3-K3 -> 50000
A4: 01324142342 | B4: M/S. Sourav Traders | C4: 01334764515 | D4: 01318105858 | E4: Haque Telecom | F4: 2108.0696 | G4: 7807 | H4: 5080 | I4: 12887 | J4: 1 | K4: 5000 | L4: 0 | M4: 0 | N4: =K4-M4 -> 5000 | O4: =M4-K4 -> -5000
A5: 01324142342 | B5: M/S. Sourav Traders | C5: 01334764501 | D5: 01907313755 | E5: PORSHI CLOTH STORE | F5: 6766.9138 | G5: 1000 | H5: 0 | I5: 1000 | J5: 1 | K5: 5000 | L5: 0 | M5: 0 | N5: =K5-M5 -> 5000 | O5: =M5-K5 -> -5000
A6: 01324142342 | B6: M/S. Sourav Traders | C6: 01324142358 | D6: 01308119080 | E6: promila telecom | F6: 1.729346 | G6: 0 | H6: 0 | I6: 0 | J6: 0 | K6: 0 | L6: 0 | M6: 0 | N6: =K6-M6 -> 0 | O6: =M6-K6 -> 0
A7: 01324142342 | B7: M/S. Sourav Traders | C7: 01334764537 | D7: 01304686867 | E7: MA COMPUTER | F7: 7965.0051 | G7: 830 | H7: 2190 | I7: 3020 | J7: 1 | K7: 5000 | L7: 0 | M7: 0 | N7: =K7-M7 -> 5000 | O7: =M7-K7 -> -5000
A8: 01324142342 | B8: M/S. Sourav Traders | C8: 01334764514 | D8: 01713688431 | E8: AKASH TELECOM | F8: 3755.2609 | G8: 4165 | H8: 5290 | I8: 9455 | J8: 0 | K8: 0 | L8: 1 | M8: 10000 | N8: =K8-M8 -> -10000 | O8: =M8-K8 -> 10000
A9: 01324142342 | B9: M/S. Sourav Traders | C9: 01334764517 | D9: 01314222961 | E9: M/S TAHOMIDA MEDICINE CORNER | F9: 0.42815 | G9: 0 | H9: 0 | I9: 0 | J9: 0 | K9: 0 | L9: 0 | M9: 0 | N9: =K9-M9 -> 0 | O9: =M9-K9 -> 0
A10: 01324142342 | B10: M/S. Sourav Traders | C10: 01324142344 | D10: 01785405090 | E10: HOME DIGITAL STUDIO | F10: 21.624949 | G10: 0 | H10: 0 | I10: 0 | J10: 0 | K10: 0 | L10: 0 | M10: 0 | N10: =K10-M10 -> 0 | O10: =M10-K10 -> 0
A11: 01324142342 | B11: M/S. Sourav Traders | C11: 01334764513 | D11: 01314633877 | E11: BAYOZID TELICOM | F11: 0.594461 | G11: 0 | H11: 0 | I11: 0 | J11: 0 | K11: 0 | L11: 0 | M11: 0 | N11: =K11-M11 -> 0 | O11: =M11-K11 -> 0
A12: 01324142342 | B12: M/S. Sourav Traders | C12: 01334764516 | D12: 01795305151 | E12: HABIBULLAH VARIETIES STORE | F12: 77.148795 | G12: 0 | H12: 0 | I12: 0 | J12: 0 | K12: 0 | L12: 0 | M12: 0 | N12: =K12-M12 -> 0 | O12: =M12-K12 -> 0
A13: 01324142342 | B13: M/S. Sourav Traders | C13: 01334764535 | D13: 01768717930 | E13: HRIDOY VARIETIES STORE | F13: 12820.316 | G13: 7700 | H13: 8500 | I13: 16200 | J13: 0 | K13: 0 | L13: 1 | M13: 5000 | N13: =K13-M13 -> -5000 | O13: =M13-K13 -> 5000
... A2410: 01324142342 | B2410: M/S. Sourav Traders | C2410: 01334764514 | D2410: 01300161010 | E2410: SAID HOMEO HALL | F2410: 29.2391 | G2410: 0 | H2410: 0 | I2410: 0 | J2410: 0 | K2410: 0 | L2410: 0 | M2410: 0 | N2410: =K2410-M2410 -> 0 | O2410: =M2410-K2410 -> 0
A2411: 01324142342 | B2411: M/S. Sourav Traders | C2411: 01334764506 | D2411: 01785384666 | E2411: Tanjina Varities Store, | F2411: 958.08275 | G2411: 2300 | H2411: 6412 | I2411: 8712 | J2411: 0 | K2411: 0 | L2411: 1 | M2411: 4000
A2412: 01324142342 | B2412: M/S. Sourav Traders | C2412: 01334764522 | D2412: 01796080444 | E2412: Cornofully Stationary | F2412: 147028.92 | G2412: 12680 | H2412: 45830 | I2412: 58510 | J2412: 0 | K2412: 0 | L2412: 1 | M2412: 50000
A2413: 01324142342 | B2413: M/S. Sourav Traders | C2413: 01334764502 | D2413: 01317130444 | E2413: MITHILA COSMETICS AND VERAITIES STORE | F2413: 51.44455 | G2413: 9830 | H2413: 500 | I2413: 10330 | J2413: 1 | K2413: 10000 | L2413: 0 | M2413: 0
A2414: 01324142342 | B2414: M/S. Sourav Traders | C2414: 01334764509 | D2414: 01300139414 | E2414: M/S Tahera Traders, | F2414: 3.9764014 | G2414: 0 | H2414: 0 | I2414: 0 | J2414: 0 | K2414: 0 | L2414: 0 | M2414: 0
A2415: 01324142342 | B2415: M/S. Sourav Traders | C2415: 01304726154 | D2415: 01328614325 | E2415: CHOWDHURY TELECOM | F2415: 4.7154 | G2415: 0 | H2415: 0 | I2415: 0 | J2415: 0 | K2415: 0 | L2415: 0 | M2415: 0
A2416: 01324142342 | B2416: M/S. Sourav Traders | C2416: 01334764537 | D2416: 01717716404 | E2416: MARIUM COS: AND KHELAGHOR | G2416: 0 | H2416: 0 | I2416: 0 | J2416: 0 | K2416: 0 | L2416: 0 | M2416: 0
A2417: 01324142342 | B2417: M/S. Sourav Traders | C2417: 01334764514 | D2417: 01744098055 | E2417: RAFI STUDIO AND MULTIMEDIA | G2417: 0 | H2417: 0 | I2417: 0 | J2417: 0 | K2417: 0 | L2417: 0 | M2417: 0
A2418: 01324142342 | B2418: M/S. Sourav Traders | C2418: 01334764514 | D2418: 01772696008 | E2418: UNIQUE MART | G2418: 0 | H2418: 0 | I2418: 0 | J2418: 0 | K2418: 0 | L2418: 0 | M2418: 0
A2419: 01324142342 | C2419: 01334764536 | G2419: 0 | H2419: 0 | I2419: 0 | J2419: 0 | K2419: 0 | L2419: 0 | M2419: 0
A2420: 01324142342 | C2420: 01334764516 | G2420: 0 | H2420: 0 | I2420: 0 | J2420: 0 | K2420: 0 | L2420: 0 | M2420: 0
A2421: 01324142342 | C2421: 01334764537 | G2421: 0 | H2421: 0 | I2421: 0 | J2421: 0 | K2421: 0 | L2421: 0 | M2421: 0
